2022-12-07 00:09:47,246 - pywebview - DEBUG - Using WinForms / Chromium
2022-12-07 00:11:36,976 - pywebview - DEBUG - Using WinForms / Chromium
2022-12-07 00:11:43,533 - flaskController - ERROR - Exception on /startTest [POST]
Traceback (most recent call last):
  File "C:\Users\hygino-AI\PycharmProjects\unetplus2Tool\venv\lib\site-packages\flask\app.py", line 1820, in full_dispatch_request
    rv = self.dispatch_request()
  File "C:\Users\hygino-AI\PycharmProjects\unetplus2Tool\venv\lib\site-packages\flask\app.py", line 1796, in dispatch_request
    return self.ensure_sync(self.view_functions[rule.endpoint])(**view_args)
  File "C:\Users\hygino-AI\PycharmProjects\unetplus2Tool\venv\lib\site-packages\flask_restful\__init__.py", line 467, in wrapper
    resp = resource(*args, **kwargs)
  File "C:\Users\hygino-AI\PycharmProjects\unetplus2Tool\venv\lib\site-packages\flask\views.py", line 107, in view
    return current_app.ensure_sync(self.dispatch_request)(**kwargs)
  File "C:\Users\hygino-AI\PycharmProjects\unetplus2Tool\venv\lib\site-packages\flask_restful\__init__.py", line 582, in dispatch_request
    resp = meth(*args, **kwargs)
  File "C:\Users\hygino-AI\PycharmProjects\unetplus2Tool\flaskController.py", line 260, in post
    Unet.Test(Model_name = ckptName,           # 학습했던 모델 경로
  File "C:\Users\hygino-AI\PycharmProjects\unetplus2Tool\Unet.py", line 577, in Test
    os.mkdir('./src/model/%s/result/test_result'%(Model_name))
FileNotFoundError: [WinError 3] 지정된 경로를 찾을 수 없습니다: './src/model/test.pth/result/test_result'
2022-12-07 00:12:12,713 - pywebview - DEBUG - Using WinForms / Chromium
2022-12-07 00:12:16,134 - flaskController - ERROR - Exception on /getImgBase64 [POST]
Traceback (most recent call last):
  File "C:\Users\hygino-AI\PycharmProjects\unetplus2Tool\venv\lib\site-packages\flask\app.py", line 1820, in full_dispatch_request
    rv = self.dispatch_request()
  File "C:\Users\hygino-AI\PycharmProjects\unetplus2Tool\venv\lib\site-packages\flask\app.py", line 1796, in dispatch_request
    return self.ensure_sync(self.view_functions[rule.endpoint])(**view_args)
  File "C:\Users\hygino-AI\PycharmProjects\unetplus2Tool\venv\lib\site-packages\flask_restful\__init__.py", line 467, in wrapper
    resp = resource(*args, **kwargs)
  File "C:\Users\hygino-AI\PycharmProjects\unetplus2Tool\venv\lib\site-packages\flask\views.py", line 107, in view
    return current_app.ensure_sync(self.dispatch_request)(**kwargs)
  File "C:\Users\hygino-AI\PycharmProjects\unetplus2Tool\venv\lib\site-packages\flask_restful\__init__.py", line 582, in dispatch_request
    resp = meth(*args, **kwargs)
  File "C:\Users\hygino-AI\PycharmProjects\unetplus2Tool\flaskController.py", line 165, in post
    with open(filepath, 'rb') as img:
FileNotFoundError: [Errno 2] No such file or directory: './src/result/test.pth/img/MIC1/undefined'
2022-12-07 00:12:16,395 - flaskController - ERROR - Exception on /getImgBase64 [POST]
Traceback (most recent call last):
  File "C:\Users\hygino-AI\PycharmProjects\unetplus2Tool\venv\lib\site-packages\flask\app.py", line 1820, in full_dispatch_request
    rv = self.dispatch_request()
  File "C:\Users\hygino-AI\PycharmProjects\unetplus2Tool\venv\lib\site-packages\flask\app.py", line 1796, in dispatch_request
    return self.ensure_sync(self.view_functions[rule.endpoint])(**view_args)
  File "C:\Users\hygino-AI\PycharmProjects\unetplus2Tool\venv\lib\site-packages\flask_restful\__init__.py", line 467, in wrapper
    resp = resource(*args, **kwargs)
  File "C:\Users\hygino-AI\PycharmProjects\unetplus2Tool\venv\lib\site-packages\flask\views.py", line 107, in view
    return current_app.ensure_sync(self.dispatch_request)(**kwargs)
  File "C:\Users\hygino-AI\PycharmProjects\unetplus2Tool\venv\lib\site-packages\flask_restful\__init__.py", line 582, in dispatch_request
    resp = meth(*args, **kwargs)
  File "C:\Users\hygino-AI\PycharmProjects\unetplus2Tool\flaskController.py", line 165, in post
    with open(filepath, 'rb') as img:
FileNotFoundError: [Errno 2] No such file or directory: './src/result/test.pth/img/MIC4/undefined'
2022-12-07 00:12:16,441 - flaskController - ERROR - Exception on /getImgBase64 [POST]
Traceback (most recent call last):
  File "C:\Users\hygino-AI\PycharmProjects\unetplus2Tool\venv\lib\site-packages\flask\app.py", line 1820, in full_dispatch_request
    rv = self.dispatch_request()
  File "C:\Users\hygino-AI\PycharmProjects\unetplus2Tool\venv\lib\site-packages\flask\app.py", line 1796, in dispatch_request
    return self.ensure_sync(self.view_functions[rule.endpoint])(**view_args)
  File "C:\Users\hygino-AI\PycharmProjects\unetplus2Tool\venv\lib\site-packages\flask_restful\__init__.py", line 467, in wrapper
    resp = resource(*args, **kwargs)
  File "C:\Users\hygino-AI\PycharmProjects\unetplus2Tool\venv\lib\site-packages\flask\views.py", line 107, in view
    return current_app.ensure_sync(self.dispatch_request)(**kwargs)
  File "C:\Users\hygino-AI\PycharmProjects\unetplus2Tool\venv\lib\site-packages\flask_restful\__init__.py", line 582, in dispatch_request
    resp = meth(*args, **kwargs)
  File "C:\Users\hygino-AI\PycharmProjects\unetplus2Tool\flaskController.py", line 165, in post
    with open(filepath, 'rb') as img:
FileNotFoundError: [Errno 2] No such file or directory: './src/result/test.pth/img/MIC5/undefined'
2022-12-07 00:12:28,179 - root - INFO - Traceback (most recent call last):
  File "C:\Users\hygino-AI\PycharmProjects\unetplus2Tool\flaskController.py", line 146, in post
    returnDict['MIC1Img'] = os.listdir(path + modelName + "/img/MIC1")
FileNotFoundError: [WinError 3] 지정된 경로를 찾을 수 없습니다: './src/result/test.pth/img/MIC1'

2022-12-07 00:12:42,011 - flaskController - ERROR - Exception on /startTest [POST]
Traceback (most recent call last):
  File "C:\Users\hygino-AI\PycharmProjects\unetplus2Tool\venv\lib\site-packages\flask\app.py", line 1820, in full_dispatch_request
    rv = self.dispatch_request()
  File "C:\Users\hygino-AI\PycharmProjects\unetplus2Tool\venv\lib\site-packages\flask\app.py", line 1796, in dispatch_request
    return self.ensure_sync(self.view_functions[rule.endpoint])(**view_args)
  File "C:\Users\hygino-AI\PycharmProjects\unetplus2Tool\venv\lib\site-packages\flask_restful\__init__.py", line 467, in wrapper
    resp = resource(*args, **kwargs)
  File "C:\Users\hygino-AI\PycharmProjects\unetplus2Tool\venv\lib\site-packages\flask\views.py", line 107, in view
    return current_app.ensure_sync(self.dispatch_request)(**kwargs)
  File "C:\Users\hygino-AI\PycharmProjects\unetplus2Tool\venv\lib\site-packages\flask_restful\__init__.py", line 582, in dispatch_request
    resp = meth(*args, **kwargs)
  File "C:\Users\hygino-AI\PycharmProjects\unetplus2Tool\flaskController.py", line 260, in post
    Unet.Test(Model_name = ckptName)
  File "C:\Users\hygino-AI\PycharmProjects\unetplus2Tool\Unet.py", line 577, in Test
    os.mkdir('./src/model/%s/result/test_result'%(Model_name))
FileNotFoundError: [WinError 3] 지정된 경로를 찾을 수 없습니다: './src/model/test.pth/result/test_result'
2022-12-07 00:13:01,227 - pywebview - DEBUG - Using WinForms / Chromium
2022-12-07 00:13:03,659 - flaskController - ERROR - Exception on /getImgBase64 [POST]
Traceback (most recent call last):
  File "C:\Users\hygino-AI\PycharmProjects\unetplus2Tool\venv\lib\site-packages\flask\app.py", line 1820, in full_dispatch_request
    rv = self.dispatch_request()
  File "C:\Users\hygino-AI\PycharmProjects\unetplus2Tool\venv\lib\site-packages\flask\app.py", line 1796, in dispatch_request
    return self.ensure_sync(self.view_functions[rule.endpoint])(**view_args)
  File "C:\Users\hygino-AI\PycharmProjects\unetplus2Tool\venv\lib\site-packages\flask_restful\__init__.py", line 467, in wrapper
    resp = resource(*args, **kwargs)
  File "C:\Users\hygino-AI\PycharmProjects\unetplus2Tool\venv\lib\site-packages\flask\views.py", line 107, in view
    return current_app.ensure_sync(self.dispatch_request)(**kwargs)
  File "C:\Users\hygino-AI\PycharmProjects\unetplus2Tool\venv\lib\site-packages\flask_restful\__init__.py", line 582, in dispatch_request
    resp = meth(*args, **kwargs)
  File "C:\Users\hygino-AI\PycharmProjects\unetplus2Tool\flaskController.py", line 165, in post
    with open(filepath, 'rb') as img:
FileNotFoundError: [Errno 2] No such file or directory: './src/result/test.pth/img/MIC1/undefined'
2022-12-07 00:13:03,979 - flaskController - ERROR - Exception on /getImgBase64 [POST]
Traceback (most recent call last):
  File "C:\Users\hygino-AI\PycharmProjects\unetplus2Tool\venv\lib\site-packages\flask\app.py", line 1820, in full_dispatch_request
    rv = self.dispatch_request()
  File "C:\Users\hygino-AI\PycharmProjects\unetplus2Tool\venv\lib\site-packages\flask\app.py", line 1796, in dispatch_request
    return self.ensure_sync(self.view_functions[rule.endpoint])(**view_args)
  File "C:\Users\hygino-AI\PycharmProjects\unetplus2Tool\venv\lib\site-packages\flask_restful\__init__.py", line 467, in wrapper
    resp = resource(*args, **kwargs)
  File "C:\Users\hygino-AI\PycharmProjects\unetplus2Tool\venv\lib\site-packages\flask\views.py", line 107, in view
    return current_app.ensure_sync(self.dispatch_request)(**kwargs)
  File "C:\Users\hygino-AI\PycharmProjects\unetplus2Tool\venv\lib\site-packages\flask_restful\__init__.py", line 582, in dispatch_request
    resp = meth(*args, **kwargs)
  File "C:\Users\hygino-AI\PycharmProjects\unetplus2Tool\flaskController.py", line 165, in post
    with open(filepath, 'rb') as img:
FileNotFoundError: [Errno 2] No such file or directory: './src/result/test.pth/img/MIC4/undefined'
2022-12-07 00:13:04,227 - flaskController - ERROR - Exception on /getImgBase64 [POST]
Traceback (most recent call last):
  File "C:\Users\hygino-AI\PycharmProjects\unetplus2Tool\venv\lib\site-packages\flask\app.py", line 1820, in full_dispatch_request
    rv = self.dispatch_request()
  File "C:\Users\hygino-AI\PycharmProjects\unetplus2Tool\venv\lib\site-packages\flask\app.py", line 1796, in dispatch_request
    return self.ensure_sync(self.view_functions[rule.endpoint])(**view_args)
  File "C:\Users\hygino-AI\PycharmProjects\unetplus2Tool\venv\lib\site-packages\flask_restful\__init__.py", line 467, in wrapper
    resp = resource(*args, **kwargs)
  File "C:\Users\hygino-AI\PycharmProjects\unetplus2Tool\venv\lib\site-packages\flask\views.py", line 107, in view
    return current_app.ensure_sync(self.dispatch_request)(**kwargs)
  File "C:\Users\hygino-AI\PycharmProjects\unetplus2Tool\venv\lib\site-packages\flask_restful\__init__.py", line 582, in dispatch_request
    resp = meth(*args, **kwargs)
  File "C:\Users\hygino-AI\PycharmProjects\unetplus2Tool\flaskController.py", line 165, in post
    with open(filepath, 'rb') as img:
FileNotFoundError: [Errno 2] No such file or directory: './src/result/test.pth/img/MIC5/undefined'
2022-12-07 00:13:32,678 - flaskController - ERROR - Exception on /startTest [POST]
Traceback (most recent call last):
  File "C:\Users\hygino-AI\PycharmProjects\unetplus2Tool\venv\lib\site-packages\flask\app.py", line 1820, in full_dispatch_request
    rv = self.dispatch_request()
  File "C:\Users\hygino-AI\PycharmProjects\unetplus2Tool\venv\lib\site-packages\flask\app.py", line 1796, in dispatch_request
    return self.ensure_sync(self.view_functions[rule.endpoint])(**view_args)
  File "C:\Users\hygino-AI\PycharmProjects\unetplus2Tool\venv\lib\site-packages\flask_restful\__init__.py", line 467, in wrapper
    resp = resource(*args, **kwargs)
  File "C:\Users\hygino-AI\PycharmProjects\unetplus2Tool\venv\lib\site-packages\flask\views.py", line 107, in view
    return current_app.ensure_sync(self.dispatch_request)(**kwargs)
  File "C:\Users\hygino-AI\PycharmProjects\unetplus2Tool\venv\lib\site-packages\flask_restful\__init__.py", line 582, in dispatch_request
    resp = meth(*args, **kwargs)
  File "C:\Users\hygino-AI\PycharmProjects\unetplus2Tool\flaskController.py", line 260, in post
    Unet.Test(Model_name = ckptName)
  File "C:\Users\hygino-AI\PycharmProjects\unetplus2Tool\Unet.py", line 662, in Test
    cv2.imwrite("./src/result/" + Model_name + "/img/MIC1/", img)
cv2.error: OpenCV(4.6.0) D:\a\opencv-python\opencv-python\opencv\modules\imgcodecs\src\loadsave.cpp:730: error: (-2:Unspecified error) could not find a writer for the specified extension in function 'cv::imwrite_'

2022-12-07 00:14:59,835 - pywebview - DEBUG - Using WinForms / Chromium
2022-12-07 00:15:23,450 - flaskController - ERROR - Exception on /startTest [POST]
Traceback (most recent call last):
  File "C:\Users\hygino-AI\PycharmProjects\unetplus2Tool\venv\lib\site-packages\flask\app.py", line 1820, in full_dispatch_request
    rv = self.dispatch_request()
  File "C:\Users\hygino-AI\PycharmProjects\unetplus2Tool\venv\lib\site-packages\flask\app.py", line 1796, in dispatch_request
    return self.ensure_sync(self.view_functions[rule.endpoint])(**view_args)
  File "C:\Users\hygino-AI\PycharmProjects\unetplus2Tool\venv\lib\site-packages\flask_restful\__init__.py", line 467, in wrapper
    resp = resource(*args, **kwargs)
  File "C:\Users\hygino-AI\PycharmProjects\unetplus2Tool\venv\lib\site-packages\flask\views.py", line 107, in view
    return current_app.ensure_sync(self.dispatch_request)(**kwargs)
  File "C:\Users\hygino-AI\PycharmProjects\unetplus2Tool\venv\lib\site-packages\flask_restful\__init__.py", line 582, in dispatch_request
    resp = meth(*args, **kwargs)
  File "C:\Users\hygino-AI\PycharmProjects\unetplus2Tool\flaskController.py", line 260, in post
    Unet.Test(Model_name = ckptName)
  File "C:\Users\hygino-AI\PycharmProjects\unetplus2Tool\Unet.py", line 668, in Test
    blend_img = cv2.add(img, masks)
cv2.error: OpenCV(4.6.0) D:\a\opencv-python\opencv-python\opencv\modules\core\src\arithm.cpp:674: error: (-5:Bad argument) When the input arrays in add/subtract/multiply/divide functions have different types, the output array type must be explicitly specified in function 'cv::arithm_op'

2022-12-07 10:48:31,348 - pywebview - DEBUG - Using WinForms / Chromium
2022-12-07 12:05:18,058 - pywebview - DEBUG - Using WinForms / Chromium
2022-12-07 12:05:42,106 - flaskController - ERROR - Exception on /startTest [POST]
Traceback (most recent call last):
  File "C:\Users\hygino-AI\PycharmProjects\unetplus2Tool\venv\lib\site-packages\flask\app.py", line 1820, in full_dispatch_request
    rv = self.dispatch_request()
  File "C:\Users\hygino-AI\PycharmProjects\unetplus2Tool\venv\lib\site-packages\flask\app.py", line 1796, in dispatch_request
    return self.ensure_sync(self.view_functions[rule.endpoint])(**view_args)
  File "C:\Users\hygino-AI\PycharmProjects\unetplus2Tool\venv\lib\site-packages\flask_restful\__init__.py", line 467, in wrapper
    resp = resource(*args, **kwargs)
  File "C:\Users\hygino-AI\PycharmProjects\unetplus2Tool\venv\lib\site-packages\flask\views.py", line 107, in view
    return current_app.ensure_sync(self.dispatch_request)(**kwargs)
  File "C:\Users\hygino-AI\PycharmProjects\unetplus2Tool\venv\lib\site-packages\flask_restful\__init__.py", line 582, in dispatch_request
    resp = meth(*args, **kwargs)
  File "C:\Users\hygino-AI\PycharmProjects\unetplus2Tool\flaskController.py", line 260, in post
    Unet.Test(Model_name = ckptName)
  File "C:\Users\hygino-AI\PycharmProjects\unetplus2Tool\Unet.py", line 640, in Test
    cv2.imshow('',image_convertor.numpy_to_cv2(prediction_mask_fault))
cv2.error: OpenCV(4.6.0) D:\a\opencv-python\opencv-python\opencv\modules\highgui\src\window.cpp:1267: error: (-2:Unspecified error) The function is not implemented. Rebuild the library with Windows, GTK+ 2.x or Cocoa support. If you are on Ubuntu or Debian, install libgtk2.0-dev and pkg-config, then re-run cmake or configure script in function 'cvShowImage'

2022-12-07 12:06:53,954 - pywebview - DEBUG - Using WinForms / Chromium
2022-12-07 12:06:57,044 - flaskController - ERROR - Exception on /getImgBase64 [POST]
Traceback (most recent call last):
  File "C:\Users\hygino-AI\PycharmProjects\unetplus2Tool\venv\lib\site-packages\flask\app.py", line 1820, in full_dispatch_request
    rv = self.dispatch_request()
  File "C:\Users\hygino-AI\PycharmProjects\unetplus2Tool\venv\lib\site-packages\flask\app.py", line 1796, in dispatch_request
    return self.ensure_sync(self.view_functions[rule.endpoint])(**view_args)
  File "C:\Users\hygino-AI\PycharmProjects\unetplus2Tool\venv\lib\site-packages\flask_restful\__init__.py", line 467, in wrapper
    resp = resource(*args, **kwargs)
  File "C:\Users\hygino-AI\PycharmProjects\unetplus2Tool\venv\lib\site-packages\flask\views.py", line 107, in view
    return current_app.ensure_sync(self.dispatch_request)(**kwargs)
  File "C:\Users\hygino-AI\PycharmProjects\unetplus2Tool\venv\lib\site-packages\flask_restful\__init__.py", line 582, in dispatch_request
    resp = meth(*args, **kwargs)
  File "C:\Users\hygino-AI\PycharmProjects\unetplus2Tool\flaskController.py", line 165, in post
    with open(filepath, 'rb') as img:
FileNotFoundError: [Errno 2] No such file or directory: './src/result/model.pth/img/MIC1/undefined'
2022-12-07 12:06:57,310 - flaskController - ERROR - Exception on /getImgBase64 [POST]
Traceback (most recent call last):
  File "C:\Users\hygino-AI\PycharmProjects\unetplus2Tool\venv\lib\site-packages\flask\app.py", line 1820, in full_dispatch_request
    rv = self.dispatch_request()
  File "C:\Users\hygino-AI\PycharmProjects\unetplus2Tool\venv\lib\site-packages\flask\app.py", line 1796, in dispatch_request
    return self.ensure_sync(self.view_functions[rule.endpoint])(**view_args)
  File "C:\Users\hygino-AI\PycharmProjects\unetplus2Tool\venv\lib\site-packages\flask_restful\__init__.py", line 467, in wrapper
    resp = resource(*args, **kwargs)
  File "C:\Users\hygino-AI\PycharmProjects\unetplus2Tool\venv\lib\site-packages\flask\views.py", line 107, in view
    return current_app.ensure_sync(self.dispatch_request)(**kwargs)
  File "C:\Users\hygino-AI\PycharmProjects\unetplus2Tool\venv\lib\site-packages\flask_restful\__init__.py", line 582, in dispatch_request
    resp = meth(*args, **kwargs)
  File "C:\Users\hygino-AI\PycharmProjects\unetplus2Tool\flaskController.py", line 165, in post
    with open(filepath, 'rb') as img:
FileNotFoundError: [Errno 2] No such file or directory: './src/result/model.pth/img/MIC4/undefined'
2022-12-07 12:06:57,357 - flaskController - ERROR - Exception on /getImgBase64 [POST]
Traceback (most recent call last):
  File "C:\Users\hygino-AI\PycharmProjects\unetplus2Tool\venv\lib\site-packages\flask\app.py", line 1820, in full_dispatch_request
    rv = self.dispatch_request()
  File "C:\Users\hygino-AI\PycharmProjects\unetplus2Tool\venv\lib\site-packages\flask\app.py", line 1796, in dispatch_request
    return self.ensure_sync(self.view_functions[rule.endpoint])(**view_args)
  File "C:\Users\hygino-AI\PycharmProjects\unetplus2Tool\venv\lib\site-packages\flask_restful\__init__.py", line 467, in wrapper
    resp = resource(*args, **kwargs)
  File "C:\Users\hygino-AI\PycharmProjects\unetplus2Tool\venv\lib\site-packages\flask\views.py", line 107, in view
    return current_app.ensure_sync(self.dispatch_request)(**kwargs)
  File "C:\Users\hygino-AI\PycharmProjects\unetplus2Tool\venv\lib\site-packages\flask_restful\__init__.py", line 582, in dispatch_request
    resp = meth(*args, **kwargs)
  File "C:\Users\hygino-AI\PycharmProjects\unetplus2Tool\flaskController.py", line 165, in post
    with open(filepath, 'rb') as img:
FileNotFoundError: [Errno 2] No such file or directory: './src/result/model.pth/img/MIC5/undefined'
2022-12-07 12:07:15,868 - flaskController - ERROR - Exception on /startTest [POST]
Traceback (most recent call last):
  File "C:\Users\hygino-AI\PycharmProjects\unetplus2Tool\venv\lib\site-packages\flask\app.py", line 1820, in full_dispatch_request
    rv = self.dispatch_request()
  File "C:\Users\hygino-AI\PycharmProjects\unetplus2Tool\venv\lib\site-packages\flask\app.py", line 1796, in dispatch_request
    return self.ensure_sync(self.view_functions[rule.endpoint])(**view_args)
  File "C:\Users\hygino-AI\PycharmProjects\unetplus2Tool\venv\lib\site-packages\flask_restful\__init__.py", line 467, in wrapper
    resp = resource(*args, **kwargs)
  File "C:\Users\hygino-AI\PycharmProjects\unetplus2Tool\venv\lib\site-packages\flask\views.py", line 107, in view
    return current_app.ensure_sync(self.dispatch_request)(**kwargs)
  File "C:\Users\hygino-AI\PycharmProjects\unetplus2Tool\venv\lib\site-packages\flask_restful\__init__.py", line 582, in dispatch_request
    resp = meth(*args, **kwargs)
  File "C:\Users\hygino-AI\PycharmProjects\unetplus2Tool\flaskController.py", line 260, in post
    Unet.Test(Model_name = ckptName)
  File "C:\Users\hygino-AI\PycharmProjects\unetplus2Tool\Unet.py", line 640, in Test
    cv2.imshow('',image_convertor.numpy_to_cv2(seg_image.permute(1, 2, 0)[:, :, 2].detach().cpu().numpy().astype(np.uint8)))
cv2.error: OpenCV(4.6.0) D:\a\opencv-python\opencv-python\opencv\modules\highgui\src\window.cpp:1267: error: (-2:Unspecified error) The function is not implemented. Rebuild the library with Windows, GTK+ 2.x or Cocoa support. If you are on Ubuntu or Debian, install libgtk2.0-dev and pkg-config, then re-run cmake or configure script in function 'cvShowImage'

2022-12-07 12:10:14,753 - flaskController - ERROR - Exception on /startTest [POST]
Traceback (most recent call last):
  File "C:\Users\hygino-AI\PycharmProjects\unetplus2Tool\venv\lib\site-packages\flask\app.py", line 1820, in full_dispatch_request
    rv = self.dispatch_request()
  File "C:\Users\hygino-AI\PycharmProjects\unetplus2Tool\venv\lib\site-packages\flask\app.py", line 1796, in dispatch_request
    return self.ensure_sync(self.view_functions[rule.endpoint])(**view_args)
  File "C:\Users\hygino-AI\PycharmProjects\unetplus2Tool\venv\lib\site-packages\flask_restful\__init__.py", line 467, in wrapper
    resp = resource(*args, **kwargs)
  File "C:\Users\hygino-AI\PycharmProjects\unetplus2Tool\venv\lib\site-packages\flask\views.py", line 107, in view
    return current_app.ensure_sync(self.dispatch_request)(**kwargs)
  File "C:\Users\hygino-AI\PycharmProjects\unetplus2Tool\venv\lib\site-packages\flask_restful\__init__.py", line 582, in dispatch_request
    resp = meth(*args, **kwargs)
  File "C:\Users\hygino-AI\PycharmProjects\unetplus2Tool\flaskController.py", line 260, in post
    Unet.Test(Model_name = ckptName)
  File "C:\Users\hygino-AI\PycharmProjects\unetplus2Tool\Unet.py", line 640, in Test
    cv2.imshow('',image_convertor.numpy_to_cv2(seg_image))
cv2.error: OpenCV(4.6.0) D:\a\opencv-python\opencv-python\opencv\modules\highgui\src\window.cpp:1267: error: (-2:Unspecified error) The function is not implemented. Rebuild the library with Windows, GTK+ 2.x or Cocoa support. If you are on Ubuntu or Debian, install libgtk2.0-dev and pkg-config, then re-run cmake or configure script in function 'cvShowImage'

2022-12-07 12:11:12,957 - flaskController - ERROR - Exception on /getImgBase64 [POST]
Traceback (most recent call last):
  File "C:\Users\hygino-AI\PycharmProjects\unetplus2Tool\venv\lib\site-packages\flask\app.py", line 1820, in full_dispatch_request
    rv = self.dispatch_request()
  File "C:\Users\hygino-AI\PycharmProjects\unetplus2Tool\venv\lib\site-packages\flask\app.py", line 1796, in dispatch_request
    return self.ensure_sync(self.view_functions[rule.endpoint])(**view_args)
  File "C:\Users\hygino-AI\PycharmProjects\unetplus2Tool\venv\lib\site-packages\flask_restful\__init__.py", line 467, in wrapper
    resp = resource(*args, **kwargs)
  File "C:\Users\hygino-AI\PycharmProjects\unetplus2Tool\venv\lib\site-packages\flask\views.py", line 107, in view
    return current_app.ensure_sync(self.dispatch_request)(**kwargs)
  File "C:\Users\hygino-AI\PycharmProjects\unetplus2Tool\venv\lib\site-packages\flask_restful\__init__.py", line 582, in dispatch_request
    resp = meth(*args, **kwargs)
  File "C:\Users\hygino-AI\PycharmProjects\unetplus2Tool\flaskController.py", line 165, in post
    with open(filepath, 'rb') as img:
FileNotFoundError: [Errno 2] No such file or directory: './src/result/model.pth/img/MIC1/undefined'
2022-12-07 12:11:13,035 - flaskController - ERROR - Exception on /getImgBase64 [POST]
Traceback (most recent call last):
  File "C:\Users\hygino-AI\PycharmProjects\unetplus2Tool\venv\lib\site-packages\flask\app.py", line 1820, in full_dispatch_request
    rv = self.dispatch_request()
  File "C:\Users\hygino-AI\PycharmProjects\unetplus2Tool\venv\lib\site-packages\flask\app.py", line 1796, in dispatch_request
    return self.ensure_sync(self.view_functions[rule.endpoint])(**view_args)
  File "C:\Users\hygino-AI\PycharmProjects\unetplus2Tool\venv\lib\site-packages\flask_restful\__init__.py", line 467, in wrapper
    resp = resource(*args, **kwargs)
  File "C:\Users\hygino-AI\PycharmProjects\unetplus2Tool\venv\lib\site-packages\flask\views.py", line 107, in view
    return current_app.ensure_sync(self.dispatch_request)(**kwargs)
  File "C:\Users\hygino-AI\PycharmProjects\unetplus2Tool\venv\lib\site-packages\flask_restful\__init__.py", line 582, in dispatch_request
    resp = meth(*args, **kwargs)
  File "C:\Users\hygino-AI\PycharmProjects\unetplus2Tool\flaskController.py", line 165, in post
    with open(filepath, 'rb') as img:
FileNotFoundError: [Errno 2] No such file or directory: './src/result/model.pth/img/MIC4/undefined'
2022-12-07 12:11:13,271 - flaskController - ERROR - Exception on /getImgBase64 [POST]
Traceback (most recent call last):
  File "C:\Users\hygino-AI\PycharmProjects\unetplus2Tool\venv\lib\site-packages\flask\app.py", line 1820, in full_dispatch_request
    rv = self.dispatch_request()
  File "C:\Users\hygino-AI\PycharmProjects\unetplus2Tool\venv\lib\site-packages\flask\app.py", line 1796, in dispatch_request
    return self.ensure_sync(self.view_functions[rule.endpoint])(**view_args)
  File "C:\Users\hygino-AI\PycharmProjects\unetplus2Tool\venv\lib\site-packages\flask_restful\__init__.py", line 467, in wrapper
    resp = resource(*args, **kwargs)
  File "C:\Users\hygino-AI\PycharmProjects\unetplus2Tool\venv\lib\site-packages\flask\views.py", line 107, in view
    return current_app.ensure_sync(self.dispatch_request)(**kwargs)
  File "C:\Users\hygino-AI\PycharmProjects\unetplus2Tool\venv\lib\site-packages\flask_restful\__init__.py", line 582, in dispatch_request
    resp = meth(*args, **kwargs)
  File "C:\Users\hygino-AI\PycharmProjects\unetplus2Tool\flaskController.py", line 165, in post
    with open(filepath, 'rb') as img:
FileNotFoundError: [Errno 2] No such file or directory: './src/result/model.pth/img/MIC5/undefined'
2022-12-07 12:11:17,616 - flaskController - ERROR - Exception on /getImgBase64 [POST]
Traceback (most recent call last):
  File "C:\Users\hygino-AI\PycharmProjects\unetplus2Tool\venv\lib\site-packages\flask\app.py", line 1820, in full_dispatch_request
    rv = self.dispatch_request()
  File "C:\Users\hygino-AI\PycharmProjects\unetplus2Tool\venv\lib\site-packages\flask\app.py", line 1796, in dispatch_request
    return self.ensure_sync(self.view_functions[rule.endpoint])(**view_args)
  File "C:\Users\hygino-AI\PycharmProjects\unetplus2Tool\venv\lib\site-packages\flask_restful\__init__.py", line 467, in wrapper
    resp = resource(*args, **kwargs)
  File "C:\Users\hygino-AI\PycharmProjects\unetplus2Tool\venv\lib\site-packages\flask\views.py", line 107, in view
    return current_app.ensure_sync(self.dispatch_request)(**kwargs)
  File "C:\Users\hygino-AI\PycharmProjects\unetplus2Tool\venv\lib\site-packages\flask_restful\__init__.py", line 582, in dispatch_request
    resp = meth(*args, **kwargs)
  File "C:\Users\hygino-AI\PycharmProjects\unetplus2Tool\flaskController.py", line 165, in post
    with open(filepath, 'rb') as img:
FileNotFoundError: [Errno 2] No such file or directory: './src/result/test.pth/img/MIC4/undefined'
2022-12-07 12:11:17,883 - flaskController - ERROR - Exception on /getImgBase64 [POST]
Traceback (most recent call last):
  File "C:\Users\hygino-AI\PycharmProjects\unetplus2Tool\venv\lib\site-packages\flask\app.py", line 1820, in full_dispatch_request
    rv = self.dispatch_request()
  File "C:\Users\hygino-AI\PycharmProjects\unetplus2Tool\venv\lib\site-packages\flask\app.py", line 1796, in dispatch_request
    return self.ensure_sync(self.view_functions[rule.endpoint])(**view_args)
  File "C:\Users\hygino-AI\PycharmProjects\unetplus2Tool\venv\lib\site-packages\flask_restful\__init__.py", line 467, in wrapper
    resp = resource(*args, **kwargs)
  File "C:\Users\hygino-AI\PycharmProjects\unetplus2Tool\venv\lib\site-packages\flask\views.py", line 107, in view
    return current_app.ensure_sync(self.dispatch_request)(**kwargs)
  File "C:\Users\hygino-AI\PycharmProjects\unetplus2Tool\venv\lib\site-packages\flask_restful\__init__.py", line 582, in dispatch_request
    resp = meth(*args, **kwargs)
  File "C:\Users\hygino-AI\PycharmProjects\unetplus2Tool\flaskController.py", line 165, in post
    with open(filepath, 'rb') as img:
FileNotFoundError: [Errno 2] No such file or directory: './src/result/test.pth/img/MIC5/undefined'
2022-12-07 12:11:18,991 - flaskController - ERROR - Exception on /getImgBase64 [POST]
Traceback (most recent call last):
  File "C:\Users\hygino-AI\PycharmProjects\unetplus2Tool\venv\lib\site-packages\flask\app.py", line 1820, in full_dispatch_request
    rv = self.dispatch_request()
  File "C:\Users\hygino-AI\PycharmProjects\unetplus2Tool\venv\lib\site-packages\flask\app.py", line 1796, in dispatch_request
    return self.ensure_sync(self.view_functions[rule.endpoint])(**view_args)
  File "C:\Users\hygino-AI\PycharmProjects\unetplus2Tool\venv\lib\site-packages\flask_restful\__init__.py", line 467, in wrapper
    resp = resource(*args, **kwargs)
  File "C:\Users\hygino-AI\PycharmProjects\unetplus2Tool\venv\lib\site-packages\flask\views.py", line 107, in view
    return current_app.ensure_sync(self.dispatch_request)(**kwargs)
  File "C:\Users\hygino-AI\PycharmProjects\unetplus2Tool\venv\lib\site-packages\flask_restful\__init__.py", line 582, in dispatch_request
    resp = meth(*args, **kwargs)
  File "C:\Users\hygino-AI\PycharmProjects\unetplus2Tool\flaskController.py", line 165, in post
    with open(filepath, 'rb') as img:
FileNotFoundError: [Errno 2] No such file or directory: './src/result/model.pth/img/MIC1/undefined'
2022-12-07 12:11:19,039 - flaskController - ERROR - Exception on /getImgBase64 [POST]
Traceback (most recent call last):
  File "C:\Users\hygino-AI\PycharmProjects\unetplus2Tool\venv\lib\site-packages\flask\app.py", line 1820, in full_dispatch_request
    rv = self.dispatch_request()
  File "C:\Users\hygino-AI\PycharmProjects\unetplus2Tool\venv\lib\site-packages\flask\app.py", line 1796, in dispatch_request
    return self.ensure_sync(self.view_functions[rule.endpoint])(**view_args)
  File "C:\Users\hygino-AI\PycharmProjects\unetplus2Tool\venv\lib\site-packages\flask_restful\__init__.py", line 467, in wrapper
    resp = resource(*args, **kwargs)
  File "C:\Users\hygino-AI\PycharmProjects\unetplus2Tool\venv\lib\site-packages\flask\views.py", line 107, in view
    return current_app.ensure_sync(self.dispatch_request)(**kwargs)
  File "C:\Users\hygino-AI\PycharmProjects\unetplus2Tool\venv\lib\site-packages\flask_restful\__init__.py", line 582, in dispatch_request
    resp = meth(*args, **kwargs)
  File "C:\Users\hygino-AI\PycharmProjects\unetplus2Tool\flaskController.py", line 165, in post
    with open(filepath, 'rb') as img:
FileNotFoundError: [Errno 2] No such file or directory: './src/result/model.pth/img/MIC4/undefined'
2022-12-07 12:11:19,303 - flaskController - ERROR - Exception on /getImgBase64 [POST]
Traceback (most recent call last):
  File "C:\Users\hygino-AI\PycharmProjects\unetplus2Tool\venv\lib\site-packages\flask\app.py", line 1820, in full_dispatch_request
    rv = self.dispatch_request()
  File "C:\Users\hygino-AI\PycharmProjects\unetplus2Tool\venv\lib\site-packages\flask\app.py", line 1796, in dispatch_request
    return self.ensure_sync(self.view_functions[rule.endpoint])(**view_args)
  File "C:\Users\hygino-AI\PycharmProjects\unetplus2Tool\venv\lib\site-packages\flask_restful\__init__.py", line 467, in wrapper
    resp = resource(*args, **kwargs)
  File "C:\Users\hygino-AI\PycharmProjects\unetplus2Tool\venv\lib\site-packages\flask\views.py", line 107, in view
    return current_app.ensure_sync(self.dispatch_request)(**kwargs)
  File "C:\Users\hygino-AI\PycharmProjects\unetplus2Tool\venv\lib\site-packages\flask_restful\__init__.py", line 582, in dispatch_request
    resp = meth(*args, **kwargs)
  File "C:\Users\hygino-AI\PycharmProjects\unetplus2Tool\flaskController.py", line 165, in post
    with open(filepath, 'rb') as img:
FileNotFoundError: [Errno 2] No such file or directory: './src/result/model.pth/img/MIC5/undefined'
2022-12-07 12:11:44,074 - flaskController - ERROR - Exception on /startTest [POST]
Traceback (most recent call last):
  File "C:\Users\hygino-AI\PycharmProjects\unetplus2Tool\venv\lib\site-packages\flask\app.py", line 1820, in full_dispatch_request
    rv = self.dispatch_request()
  File "C:\Users\hygino-AI\PycharmProjects\unetplus2Tool\venv\lib\site-packages\flask\app.py", line 1796, in dispatch_request
    return self.ensure_sync(self.view_functions[rule.endpoint])(**view_args)
  File "C:\Users\hygino-AI\PycharmProjects\unetplus2Tool\venv\lib\site-packages\flask_restful\__init__.py", line 467, in wrapper
    resp = resource(*args, **kwargs)
  File "C:\Users\hygino-AI\PycharmProjects\unetplus2Tool\venv\lib\site-packages\flask\views.py", line 107, in view
    return current_app.ensure_sync(self.dispatch_request)(**kwargs)
  File "C:\Users\hygino-AI\PycharmProjects\unetplus2Tool\venv\lib\site-packages\flask_restful\__init__.py", line 582, in dispatch_request
    resp = meth(*args, **kwargs)
  File "C:\Users\hygino-AI\PycharmProjects\unetplus2Tool\flaskController.py", line 260, in post
    Unet.Test(Model_name = ckptName)
  File "C:\Users\hygino-AI\PycharmProjects\unetplus2Tool\Unet.py", line 640, in Test
    cv2.imshow('',image_convertor.pil_to_cv2(seg_image))
cv2.error: OpenCV(4.6.0) D:\a\opencv-python\opencv-python\opencv\modules\highgui\src\window.cpp:1267: error: (-2:Unspecified error) The function is not implemented. Rebuild the library with Windows, GTK+ 2.x or Cocoa support. If you are on Ubuntu or Debian, install libgtk2.0-dev and pkg-config, then re-run cmake or configure script in function 'cvShowImage'

2022-12-07 12:14:04,163 - flaskController - ERROR - Exception on /startTest [POST]
Traceback (most recent call last):
  File "C:\Users\hygino-AI\PycharmProjects\unetplus2Tool\venv\lib\site-packages\flask\app.py", line 1820, in full_dispatch_request
    rv = self.dispatch_request()
  File "C:\Users\hygino-AI\PycharmProjects\unetplus2Tool\venv\lib\site-packages\flask\app.py", line 1796, in dispatch_request
    return self.ensure_sync(self.view_functions[rule.endpoint])(**view_args)
  File "C:\Users\hygino-AI\PycharmProjects\unetplus2Tool\venv\lib\site-packages\flask_restful\__init__.py", line 467, in wrapper
    resp = resource(*args, **kwargs)
  File "C:\Users\hygino-AI\PycharmProjects\unetplus2Tool\venv\lib\site-packages\flask\views.py", line 107, in view
    return current_app.ensure_sync(self.dispatch_request)(**kwargs)
  File "C:\Users\hygino-AI\PycharmProjects\unetplus2Tool\venv\lib\site-packages\flask_restful\__init__.py", line 582, in dispatch_request
    resp = meth(*args, **kwargs)
  File "C:\Users\hygino-AI\PycharmProjects\unetplus2Tool\flaskController.py", line 260, in post
    Unet.Test(Model_name = ckptName)
  File "C:\Users\hygino-AI\PycharmProjects\unetplus2Tool\Unet.py", line 640, in Test
    cv2.imshow(image_convertor.pil_to_cv2(seg_image))
cv2.error: OpenCV(4.6.0) D:\a\opencv-python\opencv-python\opencv\modules\highgui\src\window.cpp:1267: error: (-2:Unspecified error) The function is not implemented. Rebuild the library with Windows, GTK+ 2.x or Cocoa support. If you are on Ubuntu or Debian, install libgtk2.0-dev and pkg-config, then re-run cmake or configure script in function 'cvShowImage'

2022-12-07 12:19:39,299 - pywebview - DEBUG - Using WinForms / Chromium
2022-12-07 12:20:23,993 - flaskController - ERROR - Exception on /getImgBase64 [POST]
Traceback (most recent call last):
  File "C:\Users\hygino-AI\PycharmProjects\unetplus2Tool\venv\lib\site-packages\flask\app.py", line 1820, in full_dispatch_request
    rv = self.dispatch_request()
  File "C:\Users\hygino-AI\PycharmProjects\unetplus2Tool\venv\lib\site-packages\flask\app.py", line 1796, in dispatch_request
    return self.ensure_sync(self.view_functions[rule.endpoint])(**view_args)
  File "C:\Users\hygino-AI\PycharmProjects\unetplus2Tool\venv\lib\site-packages\flask_restful\__init__.py", line 467, in wrapper
    resp = resource(*args, **kwargs)
  File "C:\Users\hygino-AI\PycharmProjects\unetplus2Tool\venv\lib\site-packages\flask\views.py", line 107, in view
    return current_app.ensure_sync(self.dispatch_request)(**kwargs)
  File "C:\Users\hygino-AI\PycharmProjects\unetplus2Tool\venv\lib\site-packages\flask_restful\__init__.py", line 582, in dispatch_request
    resp = meth(*args, **kwargs)
  File "C:\Users\hygino-AI\PycharmProjects\unetplus2Tool\flaskController.py", line 165, in post
    with open(filepath, 'rb') as img:
FileNotFoundError: [Errno 2] No such file or directory: './src/result/model.pth/img/MIC1/undefined'
2022-12-07 12:20:24,259 - flaskController - ERROR - Exception on /getImgBase64 [POST]
Traceback (most recent call last):
  File "C:\Users\hygino-AI\PycharmProjects\unetplus2Tool\venv\lib\site-packages\flask\app.py", line 1820, in full_dispatch_request
    rv = self.dispatch_request()
  File "C:\Users\hygino-AI\PycharmProjects\unetplus2Tool\venv\lib\site-packages\flask\app.py", line 1796, in dispatch_request
    return self.ensure_sync(self.view_functions[rule.endpoint])(**view_args)
  File "C:\Users\hygino-AI\PycharmProjects\unetplus2Tool\venv\lib\site-packages\flask_restful\__init__.py", line 467, in wrapper
    resp = resource(*args, **kwargs)
  File "C:\Users\hygino-AI\PycharmProjects\unetplus2Tool\venv\lib\site-packages\flask\views.py", line 107, in view
    return current_app.ensure_sync(self.dispatch_request)(**kwargs)
  File "C:\Users\hygino-AI\PycharmProjects\unetplus2Tool\venv\lib\site-packages\flask_restful\__init__.py", line 582, in dispatch_request
    resp = meth(*args, **kwargs)
  File "C:\Users\hygino-AI\PycharmProjects\unetplus2Tool\flaskController.py", line 165, in post
    with open(filepath, 'rb') as img:
FileNotFoundError: [Errno 2] No such file or directory: './src/result/model.pth/img/MIC4/undefined'
2022-12-07 12:20:24,307 - flaskController - ERROR - Exception on /getImgBase64 [POST]
Traceback (most recent call last):
  File "C:\Users\hygino-AI\PycharmProjects\unetplus2Tool\venv\lib\site-packages\flask\app.py", line 1820, in full_dispatch_request
    rv = self.dispatch_request()
  File "C:\Users\hygino-AI\PycharmProjects\unetplus2Tool\venv\lib\site-packages\flask\app.py", line 1796, in dispatch_request
    return self.ensure_sync(self.view_functions[rule.endpoint])(**view_args)
  File "C:\Users\hygino-AI\PycharmProjects\unetplus2Tool\venv\lib\site-packages\flask_restful\__init__.py", line 467, in wrapper
    resp = resource(*args, **kwargs)
  File "C:\Users\hygino-AI\PycharmProjects\unetplus2Tool\venv\lib\site-packages\flask\views.py", line 107, in view
    return current_app.ensure_sync(self.dispatch_request)(**kwargs)
  File "C:\Users\hygino-AI\PycharmProjects\unetplus2Tool\venv\lib\site-packages\flask_restful\__init__.py", line 582, in dispatch_request
    resp = meth(*args, **kwargs)
  File "C:\Users\hygino-AI\PycharmProjects\unetplus2Tool\flaskController.py", line 165, in post
    with open(filepath, 'rb') as img:
FileNotFoundError: [Errno 2] No such file or directory: './src/result/model.pth/img/MIC5/undefined'
2022-12-07 12:20:43,012 - flaskController - ERROR - Exception on /startTest [POST]
Traceback (most recent call last):
  File "C:\Users\hygino-AI\PycharmProjects\unetplus2Tool\venv\lib\site-packages\flask\app.py", line 1820, in full_dispatch_request
    rv = self.dispatch_request()
  File "C:\Users\hygino-AI\PycharmProjects\unetplus2Tool\venv\lib\site-packages\flask\app.py", line 1796, in dispatch_request
    return self.ensure_sync(self.view_functions[rule.endpoint])(**view_args)
  File "C:\Users\hygino-AI\PycharmProjects\unetplus2Tool\venv\lib\site-packages\flask_restful\__init__.py", line 467, in wrapper
    resp = resource(*args, **kwargs)
  File "C:\Users\hygino-AI\PycharmProjects\unetplus2Tool\venv\lib\site-packages\flask\views.py", line 107, in view
    return current_app.ensure_sync(self.dispatch_request)(**kwargs)
  File "C:\Users\hygino-AI\PycharmProjects\unetplus2Tool\venv\lib\site-packages\flask_restful\__init__.py", line 582, in dispatch_request
    resp = meth(*args, **kwargs)
  File "C:\Users\hygino-AI\PycharmProjects\unetplus2Tool\flaskController.py", line 260, in post
    Unet.Test(Model_name = ckptName)
  File "C:\Users\hygino-AI\PycharmProjects\unetplus2Tool\Unet.py", line 640, in Test
    cv2.imshow('',image_convertor.pil_to_cv2(seg_image))
  File "C:\Users\hygino-AI\PycharmProjects\unetplus2Tool\image_convertor.py", line 6, in pil_to_cv2
    numpy_image = np.array(pil_image)
  File "C:\Users\hygino-AI\PycharmProjects\unetplus2Tool\venv\lib\site-packages\torch\_tensor.py", line 955, in __array__
    return self.numpy()
TypeError: can't convert cuda:0 device type tensor to numpy. Use Tensor.cpu() to copy the tensor to host memory first.
2022-12-07 12:26:24,389 - flaskController - ERROR - Exception on /startTest [POST]
Traceback (most recent call last):
  File "C:\Users\hygino-AI\PycharmProjects\unetplus2Tool\venv\lib\site-packages\flask\app.py", line 1820, in full_dispatch_request
    rv = self.dispatch_request()
  File "C:\Users\hygino-AI\PycharmProjects\unetplus2Tool\venv\lib\site-packages\flask\app.py", line 1796, in dispatch_request
    return self.ensure_sync(self.view_functions[rule.endpoint])(**view_args)
  File "C:\Users\hygino-AI\PycharmProjects\unetplus2Tool\venv\lib\site-packages\flask_restful\__init__.py", line 467, in wrapper
    resp = resource(*args, **kwargs)
  File "C:\Users\hygino-AI\PycharmProjects\unetplus2Tool\venv\lib\site-packages\flask\views.py", line 107, in view
    return current_app.ensure_sync(self.dispatch_request)(**kwargs)
  File "C:\Users\hygino-AI\PycharmProjects\unetplus2Tool\venv\lib\site-packages\flask_restful\__init__.py", line 582, in dispatch_request
    resp = meth(*args, **kwargs)
  File "C:\Users\hygino-AI\PycharmProjects\unetplus2Tool\flaskController.py", line 260, in post
    Unet.Test(Model_name = ckptName)
  File "C:\Users\hygino-AI\PycharmProjects\unetplus2Tool\Unet.py", line 640, in Test
    cv2.imshow('',image_convertor.numpy_to_cv2(seg_image))
  File "C:\Users\hygino-AI\PycharmProjects\unetplus2Tool\image_convertor.py", line 6, in pil_to_cv2
    numpy_image = np.array(pil_image)
  File "C:\Users\hygino-AI\PycharmProjects\unetplus2Tool\venv\lib\site-packages\torch\_tensor.py", line 955, in __array__
    return self.numpy()
TypeError: can't convert cuda:0 device type tensor to numpy. Use Tensor.cpu() to copy the tensor to host memory first.
2022-12-07 12:26:56,884 - flaskController - ERROR - Exception on /startTest [POST]
Traceback (most recent call last):
  File "C:\Users\hygino-AI\PycharmProjects\unetplus2Tool\venv\lib\site-packages\flask\app.py", line 1820, in full_dispatch_request
    rv = self.dispatch_request()
  File "C:\Users\hygino-AI\PycharmProjects\unetplus2Tool\venv\lib\site-packages\flask\app.py", line 1796, in dispatch_request
    return self.ensure_sync(self.view_functions[rule.endpoint])(**view_args)
  File "C:\Users\hygino-AI\PycharmProjects\unetplus2Tool\venv\lib\site-packages\flask_restful\__init__.py", line 467, in wrapper
    resp = resource(*args, **kwargs)
  File "C:\Users\hygino-AI\PycharmProjects\unetplus2Tool\venv\lib\site-packages\flask\views.py", line 107, in view
    return current_app.ensure_sync(self.dispatch_request)(**kwargs)
  File "C:\Users\hygino-AI\PycharmProjects\unetplus2Tool\venv\lib\site-packages\flask_restful\__init__.py", line 582, in dispatch_request
    resp = meth(*args, **kwargs)
  File "C:\Users\hygino-AI\PycharmProjects\unetplus2Tool\flaskController.py", line 260, in post
    Unet.Test(Model_name = ckptName)
  File "C:\Users\hygino-AI\PycharmProjects\unetplus2Tool\Unet.py", line 640, in Test
    cv2.imshow('',image_convertor.numpy_to_cv2(seg_image.permute(1, 2, 0)[:, :, 3].detach().cpu().numpy().astype(np.uint8)))
  File "C:\Users\hygino-AI\PycharmProjects\unetplus2Tool\image_convertor.py", line 6, in pil_to_cv2
    numpy_image = np.array(pil_image)
  File "C:\Users\hygino-AI\PycharmProjects\unetplus2Tool\venv\lib\site-packages\torch\_tensor.py", line 955, in __array__
    return self.numpy()
TypeError: can't convert cuda:0 device type tensor to numpy. Use Tensor.cpu() to copy the tensor to host memory first.
2022-12-07 12:28:24,182 - flaskController - ERROR - Exception on /startTest [POST]
Traceback (most recent call last):
  File "C:\Users\hygino-AI\PycharmProjects\unetplus2Tool\venv\lib\site-packages\flask\app.py", line 1820, in full_dispatch_request
    rv = self.dispatch_request()
  File "C:\Users\hygino-AI\PycharmProjects\unetplus2Tool\venv\lib\site-packages\flask\app.py", line 1796, in dispatch_request
    return self.ensure_sync(self.view_functions[rule.endpoint])(**view_args)
  File "C:\Users\hygino-AI\PycharmProjects\unetplus2Tool\venv\lib\site-packages\flask_restful\__init__.py", line 467, in wrapper
    resp = resource(*args, **kwargs)
  File "C:\Users\hygino-AI\PycharmProjects\unetplus2Tool\venv\lib\site-packages\flask\views.py", line 107, in view
    return current_app.ensure_sync(self.dispatch_request)(**kwargs)
  File "C:\Users\hygino-AI\PycharmProjects\unetplus2Tool\venv\lib\site-packages\flask_restful\__init__.py", line 582, in dispatch_request
    resp = meth(*args, **kwargs)
  File "C:\Users\hygino-AI\PycharmProjects\unetplus2Tool\flaskController.py", line 260, in post
    Unet.Test(Model_name = ckptName)
  File "C:\Users\hygino-AI\PycharmProjects\unetplus2Tool\Unet.py", line 640, in Test
    print(type(seg_image))
  File "C:\Users\hygino-AI\PycharmProjects\unetplus2Tool\image_convertor.py", line 6, in pil_to_cv2
    numpy_image = np.array(pil_image)
  File "C:\Users\hygino-AI\PycharmProjects\unetplus2Tool\venv\lib\site-packages\torch\_tensor.py", line 955, in __array__
    return self.numpy()
TypeError: can't convert cuda:0 device type tensor to numpy. Use Tensor.cpu() to copy the tensor to host memory first.
2022-12-07 13:19:57,794 - flaskController - ERROR - Exception on /startTest [POST]
Traceback (most recent call last):
  File "C:\Users\hygino-AI\PycharmProjects\unetplus2Tool\venv\lib\site-packages\flask\app.py", line 1820, in full_dispatch_request
    rv = self.dispatch_request()
  File "C:\Users\hygino-AI\PycharmProjects\unetplus2Tool\venv\lib\site-packages\flask\app.py", line 1796, in dispatch_request
    return self.ensure_sync(self.view_functions[rule.endpoint])(**view_args)
  File "C:\Users\hygino-AI\PycharmProjects\unetplus2Tool\venv\lib\site-packages\flask_restful\__init__.py", line 467, in wrapper
    resp = resource(*args, **kwargs)
  File "C:\Users\hygino-AI\PycharmProjects\unetplus2Tool\venv\lib\site-packages\flask\views.py", line 107, in view
    return current_app.ensure_sync(self.dispatch_request)(**kwargs)
  File "C:\Users\hygino-AI\PycharmProjects\unetplus2Tool\venv\lib\site-packages\flask_restful\__init__.py", line 582, in dispatch_request
    resp = meth(*args, **kwargs)
  File "C:\Users\hygino-AI\PycharmProjects\unetplus2Tool\flaskController.py", line 260, in post
    Unet.Test(Model_name = ckptName)
  File "C:\Users\hygino-AI\PycharmProjects\unetplus2Tool\Unet.py", line 640, in Test
    print(type(seg_image.permute(1, 2, 0)[:, :, 3].detach().cpu().numpy().astype(np.uint8)))
  File "C:\Users\hygino-AI\PycharmProjects\unetplus2Tool\image_convertor.py", line 6, in pil_to_cv2
    numpy_image = np.array(pil_image)
  File "C:\Users\hygino-AI\PycharmProjects\unetplus2Tool\venv\lib\site-packages\torch\_tensor.py", line 955, in __array__
    return self.numpy()
TypeError: can't convert cuda:0 device type tensor to numpy. Use Tensor.cpu() to copy the tensor to host memory first.
2022-12-07 13:55:03,193 - flaskController - ERROR - Exception on /startTest [POST]
Traceback (most recent call last):
  File "C:\Users\hygino-AI\PycharmProjects\unetplus2Tool\venv\lib\site-packages\flask\app.py", line 1820, in full_dispatch_request
    rv = self.dispatch_request()
  File "C:\Users\hygino-AI\PycharmProjects\unetplus2Tool\venv\lib\site-packages\flask\app.py", line 1796, in dispatch_request
    return self.ensure_sync(self.view_functions[rule.endpoint])(**view_args)
  File "C:\Users\hygino-AI\PycharmProjects\unetplus2Tool\venv\lib\site-packages\flask_restful\__init__.py", line 467, in wrapper
    resp = resource(*args, **kwargs)
  File "C:\Users\hygino-AI\PycharmProjects\unetplus2Tool\venv\lib\site-packages\flask\views.py", line 107, in view
    return current_app.ensure_sync(self.dispatch_request)(**kwargs)
  File "C:\Users\hygino-AI\PycharmProjects\unetplus2Tool\venv\lib\site-packages\flask_restful\__init__.py", line 582, in dispatch_request
    resp = meth(*args, **kwargs)
  File "C:\Users\hygino-AI\PycharmProjects\unetplus2Tool\flaskController.py", line 260, in post
    Unet.Test(Model_name = ckptName)
  File "C:\Users\hygino-AI\PycharmProjects\unetplus2Tool\Unet.py", line 640, in Test
    cv2.imshow('',image_convertor.numpy_to_cv2(seg_image.permute(1, 2, 0)[:, :, 3].detach().numpy().astype(np.uint8)))
  File "C:\Users\hygino-AI\PycharmProjects\unetplus2Tool\image_convertor.py", line 6, in pil_to_cv2
    numpy_image = np.array(pil_image)
  File "C:\Users\hygino-AI\PycharmProjects\unetplus2Tool\venv\lib\site-packages\torch\_tensor.py", line 955, in __array__
    return self.numpy()
TypeError: can't convert cuda:0 device type tensor to numpy. Use Tensor.cpu() to copy the tensor to host memory first.
2022-12-07 14:30:08,105 - flaskController - ERROR - Exception on /startTest [POST]
Traceback (most recent call last):
  File "C:\Users\hygino-AI\PycharmProjects\unetplus2Tool\venv\lib\site-packages\flask\app.py", line 1820, in full_dispatch_request
    rv = self.dispatch_request()
  File "C:\Users\hygino-AI\PycharmProjects\unetplus2Tool\venv\lib\site-packages\flask\app.py", line 1796, in dispatch_request
    return self.ensure_sync(self.view_functions[rule.endpoint])(**view_args)
  File "C:\Users\hygino-AI\PycharmProjects\unetplus2Tool\venv\lib\site-packages\flask_restful\__init__.py", line 467, in wrapper
    resp = resource(*args, **kwargs)
  File "C:\Users\hygino-AI\PycharmProjects\unetplus2Tool\venv\lib\site-packages\flask\views.py", line 107, in view
    return current_app.ensure_sync(self.dispatch_request)(**kwargs)
  File "C:\Users\hygino-AI\PycharmProjects\unetplus2Tool\venv\lib\site-packages\flask_restful\__init__.py", line 582, in dispatch_request
    resp = meth(*args, **kwargs)
  File "C:\Users\hygino-AI\PycharmProjects\unetplus2Tool\flaskController.py", line 260, in post
    Unet.Test(Model_name = ckptName)
  File "C:\Users\hygino-AI\PycharmProjects\unetplus2Tool\Unet.py", line 640, in Test
    cv2.imshow('',image_convertor.numpy_to_cv2(seg_image.permute(1, 2, 0)[:, :, 3].detach().numpy()))
  File "C:\Users\hygino-AI\PycharmProjects\unetplus2Tool\image_convertor.py", line 6, in pil_to_cv2
    numpy_image = np.array(pil_image)
  File "C:\Users\hygino-AI\PycharmProjects\unetplus2Tool\venv\lib\site-packages\torch\_tensor.py", line 955, in __array__
    return self.numpy()
TypeError: can't convert cuda:0 device type tensor to numpy. Use Tensor.cpu() to copy the tensor to host memory first.
2022-12-07 14:31:51,449 - flaskController - ERROR - Exception on /startTest [POST]
Traceback (most recent call last):
  File "C:\Users\hygino-AI\PycharmProjects\unetplus2Tool\venv\lib\site-packages\flask\app.py", line 1820, in full_dispatch_request
    rv = self.dispatch_request()
  File "C:\Users\hygino-AI\PycharmProjects\unetplus2Tool\venv\lib\site-packages\flask\app.py", line 1796, in dispatch_request
    return self.ensure_sync(self.view_functions[rule.endpoint])(**view_args)
  File "C:\Users\hygino-AI\PycharmProjects\unetplus2Tool\venv\lib\site-packages\flask_restful\__init__.py", line 467, in wrapper
    resp = resource(*args, **kwargs)
  File "C:\Users\hygino-AI\PycharmProjects\unetplus2Tool\venv\lib\site-packages\flask\views.py", line 107, in view
    return current_app.ensure_sync(self.dispatch_request)(**kwargs)
  File "C:\Users\hygino-AI\PycharmProjects\unetplus2Tool\venv\lib\site-packages\flask_restful\__init__.py", line 582, in dispatch_request
    resp = meth(*args, **kwargs)
  File "C:\Users\hygino-AI\PycharmProjects\unetplus2Tool\flaskController.py", line 260, in post
    Unet.Test(Model_name = ckptName)
  File "C:\Users\hygino-AI\PycharmProjects\unetplus2Tool\Unet.py", line 640, in Test
    end = time.time()
  File "C:\Users\hygino-AI\PycharmProjects\unetplus2Tool\image_convertor.py", line 6, in pil_to_cv2
    numpy_image = np.array(pil_image)
  File "C:\Users\hygino-AI\PycharmProjects\unetplus2Tool\venv\lib\site-packages\torch\_tensor.py", line 955, in __array__
    return self.numpy()
TypeError: can't convert cuda:0 device type tensor to numpy. Use Tensor.cpu() to copy the tensor to host memory first.
2022-12-07 14:32:25,879 - pywebview - DEBUG - Using WinForms / Chromium
2022-12-07 14:32:28,993 - flaskController - ERROR - Exception on /getImgBase64 [POST]
Traceback (most recent call last):
  File "C:\Users\hygino-AI\PycharmProjects\unetplus2Tool\venv\lib\site-packages\flask\app.py", line 1820, in full_dispatch_request
    rv = self.dispatch_request()
  File "C:\Users\hygino-AI\PycharmProjects\unetplus2Tool\venv\lib\site-packages\flask\app.py", line 1796, in dispatch_request
    return self.ensure_sync(self.view_functions[rule.endpoint])(**view_args)
  File "C:\Users\hygino-AI\PycharmProjects\unetplus2Tool\venv\lib\site-packages\flask_restful\__init__.py", line 467, in wrapper
    resp = resource(*args, **kwargs)
  File "C:\Users\hygino-AI\PycharmProjects\unetplus2Tool\venv\lib\site-packages\flask\views.py", line 107, in view
    return current_app.ensure_sync(self.dispatch_request)(**kwargs)
  File "C:\Users\hygino-AI\PycharmProjects\unetplus2Tool\venv\lib\site-packages\flask_restful\__init__.py", line 582, in dispatch_request
    resp = meth(*args, **kwargs)
  File "C:\Users\hygino-AI\PycharmProjects\unetplus2Tool\flaskController.py", line 165, in post
    with open(filepath, 'rb') as img:
FileNotFoundError: [Errno 2] No such file or directory: './src/result/model.pth/img/MIC1/undefined'
2022-12-07 14:32:29,258 - flaskController - ERROR - Exception on /getImgBase64 [POST]
Traceback (most recent call last):
  File "C:\Users\hygino-AI\PycharmProjects\unetplus2Tool\venv\lib\site-packages\flask\app.py", line 1820, in full_dispatch_request
    rv = self.dispatch_request()
  File "C:\Users\hygino-AI\PycharmProjects\unetplus2Tool\venv\lib\site-packages\flask\app.py", line 1796, in dispatch_request
    return self.ensure_sync(self.view_functions[rule.endpoint])(**view_args)
  File "C:\Users\hygino-AI\PycharmProjects\unetplus2Tool\venv\lib\site-packages\flask_restful\__init__.py", line 467, in wrapper
    resp = resource(*args, **kwargs)
  File "C:\Users\hygino-AI\PycharmProjects\unetplus2Tool\venv\lib\site-packages\flask\views.py", line 107, in view
    return current_app.ensure_sync(self.dispatch_request)(**kwargs)
  File "C:\Users\hygino-AI\PycharmProjects\unetplus2Tool\venv\lib\site-packages\flask_restful\__init__.py", line 582, in dispatch_request
    resp = meth(*args, **kwargs)
  File "C:\Users\hygino-AI\PycharmProjects\unetplus2Tool\flaskController.py", line 165, in post
    with open(filepath, 'rb') as img:
FileNotFoundError: [Errno 2] No such file or directory: './src/result/model.pth/img/MIC4/undefined'
2022-12-07 14:32:29,304 - flaskController - ERROR - Exception on /getImgBase64 [POST]
Traceback (most recent call last):
  File "C:\Users\hygino-AI\PycharmProjects\unetplus2Tool\venv\lib\site-packages\flask\app.py", line 1820, in full_dispatch_request
    rv = self.dispatch_request()
  File "C:\Users\hygino-AI\PycharmProjects\unetplus2Tool\venv\lib\site-packages\flask\app.py", line 1796, in dispatch_request
    return self.ensure_sync(self.view_functions[rule.endpoint])(**view_args)
  File "C:\Users\hygino-AI\PycharmProjects\unetplus2Tool\venv\lib\site-packages\flask_restful\__init__.py", line 467, in wrapper
    resp = resource(*args, **kwargs)
  File "C:\Users\hygino-AI\PycharmProjects\unetplus2Tool\venv\lib\site-packages\flask\views.py", line 107, in view
    return current_app.ensure_sync(self.dispatch_request)(**kwargs)
  File "C:\Users\hygino-AI\PycharmProjects\unetplus2Tool\venv\lib\site-packages\flask_restful\__init__.py", line 582, in dispatch_request
    resp = meth(*args, **kwargs)
  File "C:\Users\hygino-AI\PycharmProjects\unetplus2Tool\flaskController.py", line 165, in post
    with open(filepath, 'rb') as img:
FileNotFoundError: [Errno 2] No such file or directory: './src/result/model.pth/img/MIC5/undefined'
2022-12-07 14:32:48,054 - flaskController - ERROR - Exception on /startTest [POST]
Traceback (most recent call last):
  File "C:\Users\hygino-AI\PycharmProjects\unetplus2Tool\venv\lib\site-packages\flask\app.py", line 1820, in full_dispatch_request
    rv = self.dispatch_request()
  File "C:\Users\hygino-AI\PycharmProjects\unetplus2Tool\venv\lib\site-packages\flask\app.py", line 1796, in dispatch_request
    return self.ensure_sync(self.view_functions[rule.endpoint])(**view_args)
  File "C:\Users\hygino-AI\PycharmProjects\unetplus2Tool\venv\lib\site-packages\flask_restful\__init__.py", line 467, in wrapper
    resp = resource(*args, **kwargs)
  File "C:\Users\hygino-AI\PycharmProjects\unetplus2Tool\venv\lib\site-packages\flask\views.py", line 107, in view
    return current_app.ensure_sync(self.dispatch_request)(**kwargs)
  File "C:\Users\hygino-AI\PycharmProjects\unetplus2Tool\venv\lib\site-packages\flask_restful\__init__.py", line 582, in dispatch_request
    resp = meth(*args, **kwargs)
  File "C:\Users\hygino-AI\PycharmProjects\unetplus2Tool\flaskController.py", line 260, in post
    Unet.Test(Model_name = ckptName)
  File "C:\Users\hygino-AI\PycharmProjects\unetplus2Tool\Unet.py", line 640, in Test
    cv2.imshow('',image_convertor.numpy_to_cv2(seg_image.permute(1, 2, 0)[:, :, 3].detach().numpy().astype(np.uint8)))
TypeError: can't convert cuda:0 device type tensor to numpy. Use Tensor.cpu() to copy the tensor to host memory first.
2022-12-07 14:35:32,967 - pywebview - DEBUG - Using WinForms / Chromium
2022-12-07 14:35:36,785 - flaskController - ERROR - Exception on /getImgBase64 [POST]
Traceback (most recent call last):
  File "C:\Users\hygino-AI\PycharmProjects\unetplus2Tool\venv\lib\site-packages\flask\app.py", line 1820, in full_dispatch_request
    rv = self.dispatch_request()
  File "C:\Users\hygino-AI\PycharmProjects\unetplus2Tool\venv\lib\site-packages\flask\app.py", line 1796, in dispatch_request
    return self.ensure_sync(self.view_functions[rule.endpoint])(**view_args)
  File "C:\Users\hygino-AI\PycharmProjects\unetplus2Tool\venv\lib\site-packages\flask_restful\__init__.py", line 467, in wrapper
    resp = resource(*args, **kwargs)
  File "C:\Users\hygino-AI\PycharmProjects\unetplus2Tool\venv\lib\site-packages\flask\views.py", line 107, in view
    return current_app.ensure_sync(self.dispatch_request)(**kwargs)
  File "C:\Users\hygino-AI\PycharmProjects\unetplus2Tool\venv\lib\site-packages\flask_restful\__init__.py", line 582, in dispatch_request
    resp = meth(*args, **kwargs)
  File "C:\Users\hygino-AI\PycharmProjects\unetplus2Tool\flaskController.py", line 165, in post
    with open(filepath, 'rb') as img:
FileNotFoundError: [Errno 2] No such file or directory: './src/result/model.pth/img/MIC1/undefined'
2022-12-07 14:35:36,790 - flaskController - ERROR - Exception on /getImgBase64 [POST]
Traceback (most recent call last):
  File "C:\Users\hygino-AI\PycharmProjects\unetplus2Tool\venv\lib\site-packages\flask\app.py", line 1820, in full_dispatch_request
    rv = self.dispatch_request()
  File "C:\Users\hygino-AI\PycharmProjects\unetplus2Tool\venv\lib\site-packages\flask\app.py", line 1796, in dispatch_request
    return self.ensure_sync(self.view_functions[rule.endpoint])(**view_args)
  File "C:\Users\hygino-AI\PycharmProjects\unetplus2Tool\venv\lib\site-packages\flask_restful\__init__.py", line 467, in wrapper
    resp = resource(*args, **kwargs)
  File "C:\Users\hygino-AI\PycharmProjects\unetplus2Tool\venv\lib\site-packages\flask\views.py", line 107, in view
    return current_app.ensure_sync(self.dispatch_request)(**kwargs)
  File "C:\Users\hygino-AI\PycharmProjects\unetplus2Tool\venv\lib\site-packages\flask_restful\__init__.py", line 582, in dispatch_request
    resp = meth(*args, **kwargs)
  File "C:\Users\hygino-AI\PycharmProjects\unetplus2Tool\flaskController.py", line 165, in post
    with open(filepath, 'rb') as img:
FileNotFoundError: [Errno 2] No such file or directory: './src/result/model.pth/img/MIC4/undefined'
2022-12-07 14:35:37,108 - flaskController - ERROR - Exception on /getImgBase64 [POST]
Traceback (most recent call last):
  File "C:\Users\hygino-AI\PycharmProjects\unetplus2Tool\venv\lib\site-packages\flask\app.py", line 1820, in full_dispatch_request
    rv = self.dispatch_request()
  File "C:\Users\hygino-AI\PycharmProjects\unetplus2Tool\venv\lib\site-packages\flask\app.py", line 1796, in dispatch_request
    return self.ensure_sync(self.view_functions[rule.endpoint])(**view_args)
  File "C:\Users\hygino-AI\PycharmProjects\unetplus2Tool\venv\lib\site-packages\flask_restful\__init__.py", line 467, in wrapper
    resp = resource(*args, **kwargs)
  File "C:\Users\hygino-AI\PycharmProjects\unetplus2Tool\venv\lib\site-packages\flask\views.py", line 107, in view
    return current_app.ensure_sync(self.dispatch_request)(**kwargs)
  File "C:\Users\hygino-AI\PycharmProjects\unetplus2Tool\venv\lib\site-packages\flask_restful\__init__.py", line 582, in dispatch_request
    resp = meth(*args, **kwargs)
  File "C:\Users\hygino-AI\PycharmProjects\unetplus2Tool\flaskController.py", line 165, in post
    with open(filepath, 'rb') as img:
FileNotFoundError: [Errno 2] No such file or directory: './src/result/model.pth/img/MIC5/undefined'
2022-12-07 14:35:55,623 - flaskController - ERROR - Exception on /startTest [POST]
Traceback (most recent call last):
  File "C:\Users\hygino-AI\PycharmProjects\unetplus2Tool\venv\lib\site-packages\flask\app.py", line 1820, in full_dispatch_request
    rv = self.dispatch_request()
  File "C:\Users\hygino-AI\PycharmProjects\unetplus2Tool\venv\lib\site-packages\flask\app.py", line 1796, in dispatch_request
    return self.ensure_sync(self.view_functions[rule.endpoint])(**view_args)
  File "C:\Users\hygino-AI\PycharmProjects\unetplus2Tool\venv\lib\site-packages\flask_restful\__init__.py", line 467, in wrapper
    resp = resource(*args, **kwargs)
  File "C:\Users\hygino-AI\PycharmProjects\unetplus2Tool\venv\lib\site-packages\flask\views.py", line 107, in view
    return current_app.ensure_sync(self.dispatch_request)(**kwargs)
  File "C:\Users\hygino-AI\PycharmProjects\unetplus2Tool\venv\lib\site-packages\flask_restful\__init__.py", line 582, in dispatch_request
    resp = meth(*args, **kwargs)
  File "C:\Users\hygino-AI\PycharmProjects\unetplus2Tool\flaskController.py", line 260, in post
    Unet.Test(Model_name = ckptName)
  File "C:\Users\hygino-AI\PycharmProjects\unetplus2Tool\Unet.py", line 669, in Test
    blend_img = cv2.add(img, masks)
cv2.error: OpenCV(4.6.0) D:\a\opencv-python\opencv-python\opencv\modules\core\src\arithm.cpp:674: error: (-5:Bad argument) When the input arrays in add/subtract/multiply/divide functions have different types, the output array type must be explicitly specified in function 'cv::arithm_op'

